[rospy.client][INFO] 2015-05-29 11:02:45,458: init_node, name[/action_manager], pid[12116]
[xmlrpc][INFO] 2015-05-29 11:02:45,459: XML-RPC server binding to 0.0.0.0:0
[xmlrpc][INFO] 2015-05-29 11:02:45,459: Started XML-RPC server [http://192.168.1.13:34735/]
[rospy.impl.masterslave][INFO] 2015-05-29 11:02:45,459: _ready: http://192.168.1.13:34735/
[rospy.init][INFO] 2015-05-29 11:02:45,465: ROS Slave URI: [http://192.168.1.13:34735/]
[rospy.registration][INFO] 2015-05-29 11:02:45,466: Registering with master node http://localhost:11311
[xmlrpc][INFO] 2015-05-29 11:02:45,466: xml rpc node: starting XML-RPC server
[rospy.init][INFO] 2015-05-29 11:02:45,567: registered with master
[rospy.rosout][INFO] 2015-05-29 11:02:45,567: initializing /rosout core topic
[rospy.rosout][INFO] 2015-05-29 11:02:45,572: connected to core topic /rosout
[rospy.simtime][INFO] 2015-05-29 11:02:45,573: /use_sim_time is not set, will not subscribe to simulated time [/clock] topic
[rosout][INFO] 2015-05-29 11:02:46,077: I will subscribe to the topic current_emotion
[rospy.internal][INFO] 2015-05-29 11:02:46,087: topic[/rosout] adding connection to [/rosout], count 0
[rospy.internal][INFO] 2015-05-29 11:02:46,192: topic[/activity] adding connection to [http://192.168.1.13:32951/], count 0
[rospy.internal][INFO] 2015-05-29 11:02:46,194: topic[/activity] adding connection to [http://192.168.1.13:56835/], count 1
[rospy.internal][INFO] 2015-05-29 11:02:46,195: topic[/state_activity] adding connection to [http://192.168.1.13:50991/], count 0
[rospy.internal][INFO] 2015-05-29 11:02:46,195: topic[/current_emotion] adding connection to [http://192.168.1.13:59442/], count 0
[rospy.internal][INFO] 2015-05-29 11:02:46,224: topic[/activity] adding connection to [http://192.168.1.13:50312/], count 2
[rospy.internal][INFO] 2015-05-29 11:02:46,289: topic[/activity] adding connection to [http://192.168.1.15:51587/], count 3
[rospy.internal][INFO] 2015-05-29 11:02:46,290: topic[/activity] adding connection to [http://192.168.1.15:51587/], count 4
[rospy.internal][INFO] 2015-05-29 11:02:46,291: topic[/activity] removing connection to http://192.168.1.15:51587/
[rospy.internal][WARNING] 2015-05-29 11:02:46,291: Unknown error initiating TCP/IP socket to 192.168.1.15:40768 (http://192.168.1.15:51587/): Traceback (most recent call last):
  File "/opt/ros/indigo/lib/python2.7/dist-packages/rospy/impl/tcpros_base.py", line 555, in connect
    self.socket.connect((dest_addr, dest_port))
  File "/usr/lib/python2.7/socket.py", line 224, in meth
    return getattr(self._sock,name)(*args)
error: [Errno 104] Connection reset by peer

[rospy.internal][INFO] 2015-05-29 11:17:33,679: topic[/stop_learning] adding connection to [http://192.168.1.13:58114/], count 0
[rospy.internal][ERROR] 2015-05-29 11:17:33,709: Unable to initiate TCP/IP socket to 192.168.1.13:45127 (http://192.168.1.13:50312/): Traceback (most recent call last):
  File "/opt/ros/indigo/lib/python2.7/dist-packages/rospy/impl/tcpros_base.py", line 557, in connect
    self.read_header()
  File "/opt/ros/indigo/lib/python2.7/dist-packages/rospy/impl/tcpros_base.py", line 619, in read_header
    self._validate_header(read_ros_handshake_header(sock, self.read_buff, self.protocol.buff_size))
  File "/opt/ros/indigo/lib/python2.7/dist-packages/rospy/impl/tcpros_base.py", line 580, in _validate_header
    raise TransportInitError("remote error reported: %s"%header['error'])
TransportInitError: remote error reported: node shutting down

[rospy.internal][WARNING] 2015-05-29 11:17:33,774: Unknown error initiating TCP/IP socket to 192.168.1.13:37959 (http://192.168.1.13:59442/): Traceback (most recent call last):
  File "/opt/ros/indigo/lib/python2.7/dist-packages/rospy/impl/tcpros_base.py", line 557, in connect
    self.read_header()
  File "/opt/ros/indigo/lib/python2.7/dist-packages/rospy/impl/tcpros_base.py", line 619, in read_header
    self._validate_header(read_ros_handshake_header(sock, self.read_buff, self.protocol.buff_size))
  File "/opt/ros/indigo/lib/python2.7/dist-packages/rosgraph/network.py", line 363, in read_ros_handshake_header
    d = sock.recv(buff_size)
error: [Errno 104] Connection reset by peer

[rospy.internal][INFO] 2015-05-29 11:17:33,774: topic[/current_emotion] removing connection to http://192.168.1.13:59442/
[rospy.internal][WARNING] 2015-05-29 11:17:34,711: Unknown error initiating TCP/IP socket to 192.168.1.13:45127 (http://192.168.1.13:50312/): Traceback (most recent call last):
  File "/opt/ros/indigo/lib/python2.7/dist-packages/rospy/impl/tcpros_base.py", line 557, in connect
    self.read_header()
  File "/opt/ros/indigo/lib/python2.7/dist-packages/rospy/impl/tcpros_base.py", line 619, in read_header
    self._validate_header(read_ros_handshake_header(sock, self.read_buff, self.protocol.buff_size))
  File "/opt/ros/indigo/lib/python2.7/dist-packages/rosgraph/network.py", line 365, in read_ros_handshake_header
    raise ROSHandshakeException("connection from sender terminated before handshake header received. %s bytes were received. Please check sender for additional details."%b.tell())
ROSHandshakeException: connection from sender terminated before handshake header received. 0 bytes were received. Please check sender for additional details.

[rospy.internal][INFO] 2015-05-29 11:17:34,711: topic[/activity] removing connection to http://192.168.1.13:50312/
[rospy.core][INFO] 2015-05-29 11:17:37,700: signal_shutdown [Interaction exited]
[rospy.internal][ERROR] 2015-05-29 11:17:37,725: Unable to initiate TCP/IP socket to 192.168.1.13:51344 (http://192.168.1.13:56835/): Traceback (most recent call last):
  File "/opt/ros/indigo/lib/python2.7/dist-packages/rospy/impl/tcpros_base.py", line 557, in connect
    self.read_header()
  File "/opt/ros/indigo/lib/python2.7/dist-packages/rospy/impl/tcpros_base.py", line 619, in read_header
    self._validate_header(read_ros_handshake_header(sock, self.read_buff, self.protocol.buff_size))
  File "/opt/ros/indigo/lib/python2.7/dist-packages/rospy/impl/tcpros_base.py", line 580, in _validate_header
    raise TransportInitError("remote error reported: %s"%header['error'])
TransportInitError: remote error reported: node shutting down

[rospy.internal][INFO] 2015-05-29 11:17:37,726: topic[/rosout] removing connection to /rosout
[rospy.internal][INFO] 2015-05-29 11:17:37,726: topic[/state_activity] removing connection to http://192.168.1.13:50991/
[rospy.internal][INFO] 2015-05-29 11:17:37,726: topic[/activity] removing connection to http://192.168.1.13:32951/
[rospy.internal][INFO] 2015-05-29 11:17:37,726: topic[/activity] removing connection to http://192.168.1.13:56835/
[rospy.internal][INFO] 2015-05-29 11:17:37,727: topic[/activity] removing connection to http://192.168.1.15:51587/
[rospy.internal][INFO] 2015-05-29 11:17:37,727: topic[/stop_learning] removing connection to http://192.168.1.13:58114/
[rospy.impl.masterslave][INFO] 2015-05-29 11:17:37,727: Interaction exited
[rospy.core][INFO] 2015-05-29 11:17:37,980: signal_shutdown [atexit]
[rospy.client][INFO] 2015-05-29 11:18:00,129: init_node, name[/action_manager], pid[17257]
[xmlrpc][INFO] 2015-05-29 11:18:00,130: XML-RPC server binding to 0.0.0.0:0
[xmlrpc][INFO] 2015-05-29 11:18:00,130: Started XML-RPC server [http://192.168.1.13:37022/]
[rospy.impl.masterslave][INFO] 2015-05-29 11:18:00,130: _ready: http://192.168.1.13:37022/
[xmlrpc][INFO] 2015-05-29 11:18:00,131: xml rpc node: starting XML-RPC server
[rospy.registration][INFO] 2015-05-29 11:18:00,131: Registering with master node http://localhost:11311
[rospy.init][INFO] 2015-05-29 11:18:00,131: ROS Slave URI: [http://192.168.1.13:37022/]
[rospy.init][INFO] 2015-05-29 11:18:00,141: registered with master
[rospy.rosout][INFO] 2015-05-29 11:18:00,141: initializing /rosout core topic
[rospy.rosout][INFO] 2015-05-29 11:18:00,152: connected to core topic /rosout
[rospy.simtime][INFO] 2015-05-29 11:18:00,153: /use_sim_time is not set, will not subscribe to simulated time [/clock] topic
[rosout][INFO] 2015-05-29 11:18:00,499: I will subscribe to the topic current_emotion
[rospy.internal][INFO] 2015-05-29 11:18:00,564: topic[/activity] adding connection to [http://192.168.1.13:40325/], count 0
[rospy.internal][INFO] 2015-05-29 11:18:00,564: topic[/activity] adding connection to [http://192.168.1.13:48696/], count 0
[rospy.internal][INFO] 2015-05-29 11:18:00,568: topic[/state_activity] adding connection to [http://192.168.1.13:59152/], count 0
[rospy.internal][INFO] 2015-05-29 11:18:00,571: topic[/current_emotion] adding connection to [http://192.168.1.13:46048/], count 0
[rospy.internal][INFO] 2015-05-29 11:18:00,583: topic[/rosout] adding connection to [/rosout], count 0
[rospy.internal][INFO] 2015-05-29 11:18:00,725: topic[/activity] adding connection to [http://192.168.1.15:51587/], count 2
[rospy.internal][INFO] 2015-05-29 11:18:00,885: topic[/activity] adding connection to [http://192.168.1.13:51364/], count 3
[rospy.internal][ERROR] 2015-05-29 11:20:13,680: Unable to initiate TCP/IP socket to 192.168.1.13:50732 (http://192.168.1.13:40325/): Traceback (most recent call last):
  File "/opt/ros/indigo/lib/python2.7/dist-packages/rospy/impl/tcpros_base.py", line 557, in connect
    self.read_header()
  File "/opt/ros/indigo/lib/python2.7/dist-packages/rospy/impl/tcpros_base.py", line 619, in read_header
    self._validate_header(read_ros_handshake_header(sock, self.read_buff, self.protocol.buff_size))
  File "/opt/ros/indigo/lib/python2.7/dist-packages/rospy/impl/tcpros_base.py", line 580, in _validate_header
    raise TransportInitError("remote error reported: %s"%header['error'])
TransportInitError: remote error reported: node shutting down

[rospy.internal][WARNING] 2015-05-29 11:20:14,681: Unknown error initiating TCP/IP socket to 192.168.1.13:50732 (http://192.168.1.13:40325/): Traceback (most recent call last):
  File "/opt/ros/indigo/lib/python2.7/dist-packages/rospy/impl/tcpros_base.py", line 555, in connect
    self.socket.connect((dest_addr, dest_port))
  File "/usr/lib/python2.7/socket.py", line 224, in meth
    return getattr(self._sock,name)(*args)
error: [Errno 111] Connection refused

[rospy.internal][INFO] 2015-05-29 11:20:14,681: topic[/activity] removing connection to http://192.168.1.13:40325/
[rospy.internal][WARNING] 2015-05-29 11:27:59,939: Unknown error initiating TCP/IP socket to 192.168.1.15:40768 (http://192.168.1.15:51587/): Traceback (most recent call last):
  File "/opt/ros/indigo/lib/python2.7/dist-packages/rospy/impl/tcpros_base.py", line 555, in connect
    self.socket.connect((dest_addr, dest_port))
  File "/usr/lib/python2.7/socket.py", line 224, in meth
    return getattr(self._sock,name)(*args)
error: [Errno 111] Connection refused

[rospy.internal][INFO] 2015-05-29 11:27:59,939: topic[/activity] removing connection to http://192.168.1.15:51587/
[rospy.internal][INFO] 2015-05-29 11:28:06,657: topic[/activity] adding connection to [http://192.168.1.15:50797/], count 2
[rospy.internal][INFO] 2015-05-29 11:29:26,636: topic[/stop_learning] adding connection to [http://192.168.1.13:54453/], count 0
[rospy.internal][ERROR] 2015-05-29 11:29:26,659: Unable to initiate TCP/IP socket to 192.168.1.13:34080 (http://192.168.1.13:51364/): Traceback (most recent call last):
  File "/opt/ros/indigo/lib/python2.7/dist-packages/rospy/impl/tcpros_base.py", line 557, in connect
    self.read_header()
  File "/opt/ros/indigo/lib/python2.7/dist-packages/rospy/impl/tcpros_base.py", line 619, in read_header
    self._validate_header(read_ros_handshake_header(sock, self.read_buff, self.protocol.buff_size))
  File "/opt/ros/indigo/lib/python2.7/dist-packages/rospy/impl/tcpros_base.py", line 580, in _validate_header
    raise TransportInitError("remote error reported: %s"%header['error'])
TransportInitError: remote error reported: node shutting down

[rospy.internal][ERROR] 2015-05-29 11:29:26,672: Unable to initiate TCP/IP socket to 192.168.1.13:43749 (http://192.168.1.13:46048/): Traceback (most recent call last):
  File "/opt/ros/indigo/lib/python2.7/dist-packages/rospy/impl/tcpros_base.py", line 557, in connect
    self.read_header()
  File "/opt/ros/indigo/lib/python2.7/dist-packages/rospy/impl/tcpros_base.py", line 619, in read_header
    self._validate_header(read_ros_handshake_header(sock, self.read_buff, self.protocol.buff_size))
  File "/opt/ros/indigo/lib/python2.7/dist-packages/rospy/impl/tcpros_base.py", line 580, in _validate_header
    raise TransportInitError("remote error reported: %s"%header['error'])
TransportInitError: remote error reported: node shutting down

[rospy.internal][WARNING] 2015-05-29 11:29:27,660: Unknown error initiating TCP/IP socket to 192.168.1.13:34080 (http://192.168.1.13:51364/): Traceback (most recent call last):
  File "/opt/ros/indigo/lib/python2.7/dist-packages/rospy/impl/tcpros_base.py", line 555, in connect
    self.socket.connect((dest_addr, dest_port))
  File "/usr/lib/python2.7/socket.py", line 224, in meth
    return getattr(self._sock,name)(*args)
error: [Errno 111] Connection refused

[rospy.internal][INFO] 2015-05-29 11:29:27,660: topic[/activity] removing connection to http://192.168.1.13:51364/
[rospy.internal][WARNING] 2015-05-29 11:29:27,673: Unknown error initiating TCP/IP socket to 192.168.1.13:43749 (http://192.168.1.13:46048/): Traceback (most recent call last):
  File "/opt/ros/indigo/lib/python2.7/dist-packages/rospy/impl/tcpros_base.py", line 555, in connect
    self.socket.connect((dest_addr, dest_port))
  File "/usr/lib/python2.7/socket.py", line 224, in meth
    return getattr(self._sock,name)(*args)
error: [Errno 111] Connection refused

[rospy.internal][INFO] 2015-05-29 11:29:27,673: topic[/current_emotion] removing connection to http://192.168.1.13:46048/
[rospy.core][INFO] 2015-05-29 11:29:31,076: signal_shutdown [Interaction exited]
[rospy.internal][ERROR] 2015-05-29 11:29:31,081: Unable to initiate TCP/IP socket to 192.168.1.13:46672 (http://192.168.1.13:59152/): Traceback (most recent call last):
  File "/opt/ros/indigo/lib/python2.7/dist-packages/rospy/impl/tcpros_base.py", line 557, in connect
    self.read_header()
  File "/opt/ros/indigo/lib/python2.7/dist-packages/rospy/impl/tcpros_base.py", line 619, in read_header
    self._validate_header(read_ros_handshake_header(sock, self.read_buff, self.protocol.buff_size))
  File "/opt/ros/indigo/lib/python2.7/dist-packages/rospy/impl/tcpros_base.py", line 580, in _validate_header
    raise TransportInitError("remote error reported: %s"%header['error'])
TransportInitError: remote error reported: node shutting down

[rospy.internal][INFO] 2015-05-29 11:29:31,084: topic[/rosout] removing connection to /rosout
[rospy.internal][INFO] 2015-05-29 11:29:31,085: topic[/state_activity] removing connection to http://192.168.1.13:59152/
[rospy.internal][INFO] 2015-05-29 11:29:31,085: topic[/activity] removing connection to http://192.168.1.13:48696/
[rospy.internal][INFO] 2015-05-29 11:29:31,085: topic[/activity] removing connection to http://192.168.1.15:50797/
[rospy.internal][INFO] 2015-05-29 11:29:31,085: topic[/stop_learning] removing connection to http://192.168.1.13:54453/
[rospy.impl.masterslave][INFO] 2015-05-29 11:29:31,085: Interaction exited
[rospy.internal][WARNING] 2015-05-29 11:29:31,187: Unknown error initiating TCP/IP socket to 192.168.1.15:42680 (http://192.168.1.15:50797/): Traceback (most recent call last):
  File "/opt/ros/indigo/lib/python2.7/dist-packages/rospy/impl/tcpros_base.py", line 558, in connect
    self.local_endpoint = self.socket.getsockname()
AttributeError: 'NoneType' object has no attribute 'getsockname'

[rospy.core][INFO] 2015-05-29 11:29:31,190: signal_shutdown [atexit]
[rospy.client][INFO] 2015-05-29 11:32:11,168: init_node, name[/action_manager], pid[9321]
[xmlrpc][INFO] 2015-05-29 11:32:11,169: XML-RPC server binding to 0.0.0.0:0
[rospy.init][INFO] 2015-05-29 11:32:11,169: ROS Slave URI: [http://192.168.1.13:37270/]
[xmlrpc][INFO] 2015-05-29 11:32:11,169: Started XML-RPC server [http://192.168.1.13:37270/]
[rospy.impl.masterslave][INFO] 2015-05-29 11:32:11,169: _ready: http://192.168.1.13:37270/
[xmlrpc][INFO] 2015-05-29 11:32:11,170: xml rpc node: starting XML-RPC server
[rospy.registration][INFO] 2015-05-29 11:32:11,170: Registering with master node http://localhost:11311
[rospy.init][INFO] 2015-05-29 11:32:11,270: registered with master
[rospy.rosout][INFO] 2015-05-29 11:32:11,270: initializing /rosout core topic
[rospy.rosout][INFO] 2015-05-29 11:32:11,273: connected to core topic /rosout
[rospy.simtime][INFO] 2015-05-29 11:32:11,283: /use_sim_time is not set, will not subscribe to simulated time [/clock] topic
[rosout][INFO] 2015-05-29 11:32:11,668: I will subscribe to the topic current_emotion
[rospy.internal][INFO] 2015-05-29 11:32:11,678: topic[/current_emotion] adding connection to [http://192.168.1.13:40892/], count 0
[rospy.internal][INFO] 2015-05-29 11:32:11,680: topic[/state_activity] adding connection to [http://192.168.1.13:34850/], count 0
[rospy.internal][INFO] 2015-05-29 11:32:11,727: topic[/activity] adding connection to [http://192.168.1.13:33337/], count 0
[rospy.internal][INFO] 2015-05-29 11:32:11,727: topic[/activity] adding connection to [http://192.168.1.13:40205/], count 1
[rospy.internal][INFO] 2015-05-29 11:32:11,730: topic[/activity] adding connection to [http://192.168.1.13:40199/], count 2
[rospy.internal][INFO] 2015-05-29 11:32:11,757: topic[/activity] adding connection to [http://192.168.1.15:50797/], count 3
[rospy.internal][INFO] 2015-05-29 11:32:11,760: topic[/rosout] adding connection to [/rosout], count 0
[rospy.internal][ERROR] 2015-05-29 11:34:12,473: Unable to initiate TCP/IP socket to 192.168.1.13:56467 (http://192.168.1.13:40205/): Traceback (most recent call last):
  File "/opt/ros/indigo/lib/python2.7/dist-packages/rospy/impl/tcpros_base.py", line 557, in connect
    self.read_header()
  File "/opt/ros/indigo/lib/python2.7/dist-packages/rospy/impl/tcpros_base.py", line 619, in read_header
    self._validate_header(read_ros_handshake_header(sock, self.read_buff, self.protocol.buff_size))
  File "/opt/ros/indigo/lib/python2.7/dist-packages/rospy/impl/tcpros_base.py", line 580, in _validate_header
    raise TransportInitError("remote error reported: %s"%header['error'])
TransportInitError: remote error reported: node shutting down

[rospy.internal][WARNING] 2015-05-29 11:34:13,473: Unknown error initiating TCP/IP socket to 192.168.1.13:56467 (http://192.168.1.13:40205/): Traceback (most recent call last):
  File "/opt/ros/indigo/lib/python2.7/dist-packages/rospy/impl/tcpros_base.py", line 555, in connect
    self.socket.connect((dest_addr, dest_port))
  File "/usr/lib/python2.7/socket.py", line 224, in meth
    return getattr(self._sock,name)(*args)
error: [Errno 111] Connection refused

[rospy.internal][INFO] 2015-05-29 11:34:13,474: topic[/activity] removing connection to http://192.168.1.13:40205/
[rospy.internal][ERROR] 2015-05-29 11:41:28,613: Unable to initiate TCP/IP socket to 192.168.1.13:59046 (http://192.168.1.13:40199/): Traceback (most recent call last):
  File "/opt/ros/indigo/lib/python2.7/dist-packages/rospy/impl/tcpros_base.py", line 557, in connect
    self.read_header()
  File "/opt/ros/indigo/lib/python2.7/dist-packages/rospy/impl/tcpros_base.py", line 619, in read_header
    self._validate_header(read_ros_handshake_header(sock, self.read_buff, self.protocol.buff_size))
  File "/opt/ros/indigo/lib/python2.7/dist-packages/rospy/impl/tcpros_base.py", line 580, in _validate_header
    raise TransportInitError("remote error reported: %s"%header['error'])
TransportInitError: remote error reported: node shutting down

[rospy.internal][INFO] 2015-05-29 11:41:28,620: topic[/stop_learning] adding connection to [http://192.168.1.13:52311/], count 0
[rospy.internal][WARNING] 2015-05-29 11:41:29,614: Unknown error initiating TCP/IP socket to 192.168.1.13:59046 (http://192.168.1.13:40199/): Traceback (most recent call last):
  File "/opt/ros/indigo/lib/python2.7/dist-packages/rospy/impl/tcpros_base.py", line 555, in connect
    self.socket.connect((dest_addr, dest_port))
  File "/usr/lib/python2.7/socket.py", line 224, in meth
    return getattr(self._sock,name)(*args)
error: [Errno 111] Connection refused

[rospy.internal][INFO] 2015-05-29 11:41:29,615: topic[/activity] removing connection to http://192.168.1.13:40199/
[rospy.core][INFO] 2015-05-29 11:41:31,577: signal_shutdown [Interaction exited]
[rospy.internal][INFO] 2015-05-29 11:41:31,584: topic[/rosout] removing connection to /rosout
[rospy.internal][INFO] 2015-05-29 11:41:31,584: topic[/state_activity] removing connection to http://192.168.1.13:34850/
[rospy.internal][INFO] 2015-05-29 11:41:31,585: topic[/current_emotion] removing connection to http://192.168.1.13:40892/
[rospy.internal][INFO] 2015-05-29 11:41:31,585: topic[/activity] removing connection to http://192.168.1.13:33337/
[rospy.internal][WARNING] 2015-05-29 11:41:31,585: Unknown error initiating TCP/IP socket to 192.168.1.13:46346 (http://192.168.1.13:34850/): Traceback (most recent call last):
  File "/opt/ros/indigo/lib/python2.7/dist-packages/rospy/impl/tcpros_base.py", line 557, in connect
    self.read_header()
  File "/opt/ros/indigo/lib/python2.7/dist-packages/rospy/impl/tcpros_base.py", line 619, in read_header
    self._validate_header(read_ros_handshake_header(sock, self.read_buff, self.protocol.buff_size))
  File "/opt/ros/indigo/lib/python2.7/dist-packages/rosgraph/network.py", line 365, in read_ros_handshake_header
    raise ROSHandshakeException("connection from sender terminated before handshake header received. %s bytes were received. Please check sender for additional details."%b.tell())
ROSHandshakeException: connection from sender terminated before handshake header received. 0 bytes were received. Please check sender for additional details.

[rospy.internal][INFO] 2015-05-29 11:41:31,586: topic[/activity] removing connection to http://192.168.1.15:50797/
[rospy.internal][INFO] 2015-05-29 11:41:31,586: topic[/stop_learning] removing connection to http://192.168.1.13:52311/
[rospy.impl.masterslave][INFO] 2015-05-29 11:41:31,587: Interaction exited
[rospy.core][INFO] 2015-05-29 11:41:31,744: signal_shutdown [atexit]
[rospy.client][INFO] 2015-05-29 11:53:06,967: init_node, name[/action_manager], pid[29754]
[xmlrpc][INFO] 2015-05-29 11:53:06,967: XML-RPC server binding to 0.0.0.0:0
[xmlrpc][INFO] 2015-05-29 11:53:06,968: Started XML-RPC server [http://192.168.1.13:38384/]
[rospy.impl.masterslave][INFO] 2015-05-29 11:53:06,968: _ready: http://192.168.1.13:38384/
[rospy.init][INFO] 2015-05-29 11:53:06,968: ROS Slave URI: [http://192.168.1.13:38384/]
[xmlrpc][INFO] 2015-05-29 11:53:06,968: xml rpc node: starting XML-RPC server
[rospy.registration][INFO] 2015-05-29 11:53:06,969: Registering with master node http://localhost:11311
[rospy.init][INFO] 2015-05-29 11:53:07,068: registered with master
[rospy.rosout][INFO] 2015-05-29 11:53:07,069: initializing /rosout core topic
[rospy.rosout][INFO] 2015-05-29 11:53:07,071: connected to core topic /rosout
[rospy.simtime][INFO] 2015-05-29 11:53:07,073: /use_sim_time is not set, will not subscribe to simulated time [/clock] topic
[rosout][INFO] 2015-05-29 11:53:07,393: I will subscribe to the topic current_emotion
[rospy.internal][INFO] 2015-05-29 11:53:07,480: topic[/activity] adding connection to [http://192.168.1.13:48575/], count 0
[rospy.internal][INFO] 2015-05-29 11:53:07,481: topic[/activity] adding connection to [http://192.168.1.13:33273/], count 1
[rospy.internal][INFO] 2015-05-29 11:53:07,484: topic[/state_activity] adding connection to [http://192.168.1.13:57813/], count 0
[rospy.internal][INFO] 2015-05-29 11:53:07,489: topic[/rosout] adding connection to [/rosout], count 0
[rospy.internal][INFO] 2015-05-29 11:53:07,515: topic[/current_emotion] adding connection to [http://192.168.1.13:33193/], count 0
[rospy.internal][INFO] 2015-05-29 11:53:07,703: topic[/activity] adding connection to [http://192.168.1.15:50797/], count 2
[rospy.internal][INFO] 2015-05-29 11:53:07,730: topic[/activity] adding connection to [http://192.168.1.13:54139/], count 3
[rospy.internal][ERROR] 2015-05-29 11:56:14,417: Unable to initiate TCP/IP socket to 192.168.1.13:42586 (http://192.168.1.13:33193/): Traceback (most recent call last):
  File "/opt/ros/indigo/lib/python2.7/dist-packages/rospy/impl/tcpros_base.py", line 557, in connect
    self.read_header()
  File "/opt/ros/indigo/lib/python2.7/dist-packages/rospy/impl/tcpros_base.py", line 619, in read_header
    self._validate_header(read_ros_handshake_header(sock, self.read_buff, self.protocol.buff_size))
  File "/opt/ros/indigo/lib/python2.7/dist-packages/rospy/impl/tcpros_base.py", line 580, in _validate_header
    raise TransportInitError("remote error reported: %s"%header['error'])
TransportInitError: remote error reported: node shutting down

[rospy.internal][INFO] 2015-05-29 11:56:14,417: topic[/stop_learning] adding connection to [http://192.168.1.13:33186/], count 0
[rospy.internal][ERROR] 2015-05-29 11:56:14,428: Unable to initiate TCP/IP socket to 192.168.1.13:37944 (http://192.168.1.13:54139/): Traceback (most recent call last):
  File "/opt/ros/indigo/lib/python2.7/dist-packages/rospy/impl/tcpros_base.py", line 557, in connect
    self.read_header()
  File "/opt/ros/indigo/lib/python2.7/dist-packages/rospy/impl/tcpros_base.py", line 619, in read_header
    self._validate_header(read_ros_handshake_header(sock, self.read_buff, self.protocol.buff_size))
  File "/opt/ros/indigo/lib/python2.7/dist-packages/rospy/impl/tcpros_base.py", line 580, in _validate_header
    raise TransportInitError("remote error reported: %s"%header['error'])
TransportInitError: remote error reported: node shutting down

[rospy.internal][WARNING] 2015-05-29 11:56:15,419: Unknown error initiating TCP/IP socket to 192.168.1.13:42586 (http://192.168.1.13:33193/): Traceback (most recent call last):
  File "/opt/ros/indigo/lib/python2.7/dist-packages/rospy/impl/tcpros_base.py", line 555, in connect
    self.socket.connect((dest_addr, dest_port))
  File "/usr/lib/python2.7/socket.py", line 224, in meth
    return getattr(self._sock,name)(*args)
error: [Errno 111] Connection refused

[rospy.internal][INFO] 2015-05-29 11:56:15,419: topic[/current_emotion] removing connection to http://192.168.1.13:33193/
[rospy.internal][WARNING] 2015-05-29 11:56:15,430: Unknown error initiating TCP/IP socket to 192.168.1.13:37944 (http://192.168.1.13:54139/): Traceback (most recent call last):
  File "/opt/ros/indigo/lib/python2.7/dist-packages/rospy/impl/tcpros_base.py", line 555, in connect
    self.socket.connect((dest_addr, dest_port))
  File "/usr/lib/python2.7/socket.py", line 224, in meth
    return getattr(self._sock,name)(*args)
error: [Errno 111] Connection refused

[rospy.internal][INFO] 2015-05-29 11:56:15,431: topic[/activity] removing connection to http://192.168.1.13:54139/
[rospy.core][INFO] 2015-05-29 11:56:18,800: signal_shutdown [Interaction exited]
[rospy.internal][ERROR] 2015-05-29 11:56:18,806: Unable to initiate TCP/IP socket to 192.168.1.13:39608 (http://192.168.1.13:33273/): Traceback (most recent call last):
  File "/opt/ros/indigo/lib/python2.7/dist-packages/rospy/impl/tcpros_base.py", line 557, in connect
    self.read_header()
  File "/opt/ros/indigo/lib/python2.7/dist-packages/rospy/impl/tcpros_base.py", line 619, in read_header
    self._validate_header(read_ros_handshake_header(sock, self.read_buff, self.protocol.buff_size))
  File "/opt/ros/indigo/lib/python2.7/dist-packages/rospy/impl/tcpros_base.py", line 580, in _validate_header
    raise TransportInitError("remote error reported: %s"%header['error'])
TransportInitError: remote error reported: node shutting down

[rospy.internal][INFO] 2015-05-29 11:56:18,808: topic[/rosout] removing connection to /rosout
[rospy.internal][INFO] 2015-05-29 11:56:18,808: topic[/state_activity] removing connection to http://192.168.1.13:57813/
[rospy.internal][INFO] 2015-05-29 11:56:18,809: topic[/activity] removing connection to http://192.168.1.13:48575/
[rospy.internal][INFO] 2015-05-29 11:56:18,809: topic[/activity] removing connection to http://192.168.1.13:33273/
[rospy.internal][INFO] 2015-05-29 11:56:18,809: topic[/activity] removing connection to http://192.168.1.15:50797/
[rospy.internal][INFO] 2015-05-29 11:56:18,810: topic[/stop_learning] removing connection to http://192.168.1.13:33186/
[rospy.impl.masterslave][INFO] 2015-05-29 11:56:18,810: Interaction exited
[rospy.core][INFO] 2015-05-29 11:56:19,168: signal_shutdown [atexit]
[rospy.client][INFO] 2015-05-29 11:58:00,252: init_node, name[/action_manager], pid[6970]
[xmlrpc][INFO] 2015-05-29 11:58:00,253: XML-RPC server binding to 0.0.0.0:0
[rospy.init][INFO] 2015-05-29 11:58:00,253: ROS Slave URI: [http://192.168.1.13:55097/]
[xmlrpc][INFO] 2015-05-29 11:58:00,253: Started XML-RPC server [http://192.168.1.13:55097/]
[rospy.impl.masterslave][INFO] 2015-05-29 11:58:00,253: _ready: http://192.168.1.13:55097/
[rospy.registration][INFO] 2015-05-29 11:58:00,254: Registering with master node http://localhost:11311
[xmlrpc][INFO] 2015-05-29 11:58:00,255: xml rpc node: starting XML-RPC server
[rospy.init][INFO] 2015-05-29 11:58:00,354: registered with master
[rospy.rosout][INFO] 2015-05-29 11:58:00,354: initializing /rosout core topic
[rospy.rosout][INFO] 2015-05-29 11:58:00,356: connected to core topic /rosout
[rospy.simtime][INFO] 2015-05-29 11:58:00,358: /use_sim_time is not set, will not subscribe to simulated time [/clock] topic
[rosout][INFO] 2015-05-29 11:58:00,701: I will subscribe to the topic current_emotion
[rospy.internal][INFO] 2015-05-29 11:58:00,794: topic[/current_emotion] adding connection to [http://192.168.1.13:38600/], count 0
[rospy.internal][INFO] 2015-05-29 11:58:00,795: topic[/activity] adding connection to [http://192.168.1.13:38611/], count 0
[rospy.internal][INFO] 2015-05-29 11:58:00,795: topic[/activity] adding connection to [http://192.168.1.13:50649/], count 1
[rospy.internal][INFO] 2015-05-29 11:58:00,795: topic[/rosout] adding connection to [/rosout], count 0
[rospy.internal][INFO] 2015-05-29 11:58:00,799: topic[/state_activity] adding connection to [http://192.168.1.13:35078/], count 0
[rospy.internal][INFO] 2015-05-29 11:58:00,863: topic[/activity] adding connection to [http://192.168.1.15:50797/], count 2
[rospy.internal][INFO] 2015-05-29 11:58:01,012: topic[/activity] adding connection to [http://192.168.1.13:52245/], count 3
[rospy.internal][ERROR] 2015-05-29 11:58:47,414: Unable to initiate TCP/IP socket to 192.168.1.13:45373 (http://192.168.1.13:38600/): Traceback (most recent call last):
  File "/opt/ros/indigo/lib/python2.7/dist-packages/rospy/impl/tcpros_base.py", line 557, in connect
    self.read_header()
  File "/opt/ros/indigo/lib/python2.7/dist-packages/rospy/impl/tcpros_base.py", line 619, in read_header
    self._validate_header(read_ros_handshake_header(sock, self.read_buff, self.protocol.buff_size))
  File "/opt/ros/indigo/lib/python2.7/dist-packages/rospy/impl/tcpros_base.py", line 580, in _validate_header
    raise TransportInitError("remote error reported: %s"%header['error'])
TransportInitError: remote error reported: node shutting down

[rospy.internal][INFO] 2015-05-29 11:58:47,445: topic[/stop_learning] adding connection to [http://192.168.1.13:60454/], count 0
[rospy.internal][ERROR] 2015-05-29 11:58:47,452: Unable to initiate TCP/IP socket to 192.168.1.13:42931 (http://192.168.1.13:52245/): Traceback (most recent call last):
  File "/opt/ros/indigo/lib/python2.7/dist-packages/rospy/impl/tcpros_base.py", line 557, in connect
    self.read_header()
  File "/opt/ros/indigo/lib/python2.7/dist-packages/rospy/impl/tcpros_base.py", line 619, in read_header
    self._validate_header(read_ros_handshake_header(sock, self.read_buff, self.protocol.buff_size))
  File "/opt/ros/indigo/lib/python2.7/dist-packages/rospy/impl/tcpros_base.py", line 580, in _validate_header
    raise TransportInitError("remote error reported: %s"%header['error'])
TransportInitError: remote error reported: node shutting down

[rospy.internal][WARNING] 2015-05-29 11:58:48,415: Unknown error initiating TCP/IP socket to 192.168.1.13:45373 (http://192.168.1.13:38600/): Traceback (most recent call last):
  File "/opt/ros/indigo/lib/python2.7/dist-packages/rospy/impl/tcpros_base.py", line 555, in connect
    self.socket.connect((dest_addr, dest_port))
  File "/usr/lib/python2.7/socket.py", line 224, in meth
    return getattr(self._sock,name)(*args)
error: [Errno 111] Connection refused

[rospy.internal][INFO] 2015-05-29 11:58:48,415: topic[/current_emotion] removing connection to http://192.168.1.13:38600/
[rospy.internal][WARNING] 2015-05-29 11:58:48,454: Unknown error initiating TCP/IP socket to 192.168.1.13:42931 (http://192.168.1.13:52245/): Traceback (most recent call last):
  File "/opt/ros/indigo/lib/python2.7/dist-packages/rospy/impl/tcpros_base.py", line 555, in connect
    self.socket.connect((dest_addr, dest_port))
  File "/usr/lib/python2.7/socket.py", line 224, in meth
    return getattr(self._sock,name)(*args)
error: [Errno 111] Connection refused

[rospy.internal][INFO] 2015-05-29 11:58:48,455: topic[/activity] removing connection to http://192.168.1.13:52245/
[rospy.internal][WARNING] 2015-05-29 11:58:51,834: Unknown error initiating TCP/IP socket to 192.168.1.13:38395 (http://192.168.1.13:50649/): Traceback (most recent call last):
  File "/opt/ros/indigo/lib/python2.7/dist-packages/rospy/impl/tcpros_base.py", line 557, in connect
    self.read_header()
  File "/opt/ros/indigo/lib/python2.7/dist-packages/rospy/impl/tcpros_base.py", line 619, in read_header
    self._validate_header(read_ros_handshake_header(sock, self.read_buff, self.protocol.buff_size))
  File "/opt/ros/indigo/lib/python2.7/dist-packages/rosgraph/network.py", line 363, in read_ros_handshake_header
    d = sock.recv(buff_size)
error: [Errno 104] Connection reset by peer

[rospy.internal][INFO] 2015-05-29 11:58:51,834: topic[/activity] removing connection to http://192.168.1.13:50649/
[rospy.internal][ERROR] 2015-05-29 11:58:51,837: Unable to initiate TCP/IP socket to 192.168.1.13:46113 (http://192.168.1.13:35078/): Traceback (most recent call last):
  File "/opt/ros/indigo/lib/python2.7/dist-packages/rospy/impl/tcpros_base.py", line 557, in connect
    self.read_header()
  File "/opt/ros/indigo/lib/python2.7/dist-packages/rospy/impl/tcpros_base.py", line 619, in read_header
    self._validate_header(read_ros_handshake_header(sock, self.read_buff, self.protocol.buff_size))
  File "/opt/ros/indigo/lib/python2.7/dist-packages/rospy/impl/tcpros_base.py", line 580, in _validate_header
    raise TransportInitError("remote error reported: %s"%header['error'])
TransportInitError: remote error reported: node shutting down

[rospy.core][INFO] 2015-05-29 11:58:51,837: signal_shutdown [Interaction exited]
[rospy.internal][INFO] 2015-05-29 11:58:51,842: topic[/rosout] removing connection to /rosout
[rospy.internal][INFO] 2015-05-29 11:58:51,842: topic[/state_activity] removing connection to http://192.168.1.13:35078/
[rospy.internal][INFO] 2015-05-29 11:58:51,843: topic[/activity] removing connection to http://192.168.1.13:38611/
[rospy.internal][INFO] 2015-05-29 11:58:51,843: topic[/activity] removing connection to http://192.168.1.15:50797/
[rospy.internal][INFO] 2015-05-29 11:58:51,843: topic[/stop_learning] removing connection to http://192.168.1.13:60454/
[rospy.impl.masterslave][INFO] 2015-05-29 11:58:51,844: Interaction exited
[rospy.core][INFO] 2015-05-29 11:58:51,851: signal_shutdown [atexit]
